<?xml version="1.0" ?> <!-- =================================================================================== --> <!-- |    This document was autogenerated by xacro from /home/olivier/code/ros2/install/floatgen/share/floatgen/urdf/farm.xacro | --> <!-- |    EDITING THIS FILE BY HAND IS NOT RECOMMENDED                                 | --> <!-- =================================================================================== --> <robot name="farm"> <link name="world"/> <gazebo> <plugin filename="libignition-gazebo-joint-state-publisher-system.so" name="ignition::gazebo::systems::JointStatePublisher"/> </gazebo> <joint name="turbine_1_1_world" type="fixed"> <parent link="world"/> <child link="turbine_1_1/base_link"/> <origin rpy="0 0 0.7" xyz="0.0 0.0 0"/> </joint> <link name="turbine_1_1/base_link"> <inertial> <mass value="10"/> <inertia ixx="0.4" ixy="0.0" ixz="0.0" iyy="0.4" iyz="0.0" izz="0.2"/> </inertial> <visual> <geometry> <mesh filename="file:///home/olivier/code/ros2/install/floatgen/share/floatgen/meshes/base_air.dae"/> </geometry> </visual> <visual> <geometry> <mesh filename="file:///home/olivier/code/ros2/install/floatgen/share/floatgen/meshes/base_water.dae"/> </geometry> </visual> <collision> <geometry> <mesh filename="file:///home/olivier/code/ros2/install/floatgen/share/floatgen/meshes/base_air.stl"/> </geometry> </collision> <collision> <geometry> <mesh filename="file:///home/olivier/code/ros2/install/floatgen/share/floatgen/meshes/base_water.stl"/> </geometry> </collision> </link> <joint name="turbine_1_1_floating" type="fixed"> <parent link="turbine_1_1/base_link"/> <child link="turbine_1_1/pole"/> <origin xyz="-13.5 0 0"/> </joint> <link name="turbine_1_1/pole"> <inertial> <mass value="10"/> <inertia ixx="0.4" ixy="0.0" ixz="0.0" iyy="0.4" iyz="0.0" izz="0.2"/> </inertial> <visual> <geometry> <mesh filename="file:///home/olivier/code/ros2/install/floatgen/share/floatgen/meshes/pole.dae" scale="1 1 1"/> </geometry> </visual> </link> <joint name="turbine_1_1" type="continuous"> <parent link="turbine_1_1/pole"/> <child link="turbine_1_1/blades"/> <axis xyz="1 0 0"/> <origin rpy="0.0 0 0" xyz="0.71 0.0 16.864"/> </joint> <link name="turbine_1_1/blades"> <inertial> <mass value="10"/> <inertia ixx="0.4" ixy="0.0" ixz="0.0" iyy="0.4" iyz="0.0" izz="0.2"/> </inertial> <visual> <geometry> <mesh filename="file:///home/olivier/code/ros2/install/floatgen/share/floatgen/meshes/blades.dae" scale="1 1 1"/> </geometry> </visual> </link> <gazebo> <plugin filename="libignition-gazebo-joint-controller-system.so" name="ignition::gazebo::systems::JointController"> <joint_name>turbine_1_1</joint_name> <initial_velocity>-2.0</initial_velocity> </plugin> </gazebo> </robot>
